Workbook
Name Activity: [1]names_1!$B$10:$B$17
Name ActivitySet: [1]names!$A$10:$A$12

Sheet Cover Sheet
B1: v3.07V | J1: WELL REPORT | AE1: DO NOT ADD | AJ1: DO NOT ADD | AK1: DO NOT | AM1: Corey! You can only add things to the lists in light green
B2: WSG | C2: WELL REPORT | U2: WIRELINE SERVICES GROUP | AE2: ANYthing else to this list!!! | AJ2: ANY TOOLS!!! | AK2: EDIT | AM2: But for the love of DPC just ask us to change things :) | AY2: This list is auto generated by copying the VC sheet | BI2: Don’t touch or rusty will be mad
B3: DPC_Project | D3: RTIO BROCKMAN | H3: =IF(IFERROR(VLOOKUP(D3,AS5:AU80,2,FALSE),"NO_ERROR")<>"NO_ERROR","",IF(D3="","","UNKNOWN DPC PROJECT!")) | AE3: u will break DPC | AJ3: u will break DPC | BI3: ="Dip = " & J12 -> Dip = -90 | BJ3: =IF(K12="From Horizontal",1,-1) -> 1
B4: Client | D4: =IF(IFERROR(VLOOKUP(D3,AS5:AU80,2,FALSE),D3)=0,"",IFERROR(VLOOKUP(D3,AS5:AU80,2,FALSE),D3)) -> RIO TINTO IRON ORE | I4: Job Number | J4: P5042 | Q4: Acquisition Interval (cm) | S4: 10 | U4: Safety - Service - Integrity - Excellence | AE4: Measure Point | AF4: Run | AG4: Planned Dip | AH4: Yes/No/NS | AI4: Drill Type | AJ4: Tool Type | AK4: Depth corr | AL4: DATUM | AM4: Source list | AN4: MUD TYPE | AO4: Units | AP4: AMG Zones | AQ4: Scale List | AR4: STATE | AS4: DPC_Project | AT4: Client List | AU4: RTIOHub | AV4: Country | AX4: Comments for clients | AY4: Full Names | AZ4: Name Acronyms | BA4: ClientDipOrientation | BB4: ClientDatum | BC4: ClientZone | BD4: ToolSerial | BE4: ToolType | BI4: 0 | BJ4: 0
B5: RTIO HUB | D5: =IF(IFERROR(VLOOKUP(D3,AS5:AU80,3,FALSE),"")=0,"",IFERROR(VLOOKUP(D3,AS5:AU80,3,FALSE),"")) -> BROCKMAN | AG5: From Vertical | AM5: - | AN5: - | AO5: cm | AS5: - | AT5: - | AX5: NO SURVEY - HOLE BLOCKED AT XXm | AY5: AA | AZ5: ARGJEND AVDIU | BD5: 2665 | BE5: 9622 | BI5: =COS(RADIANS(J12))*10 -> 6.1257423e-16 | BJ5: =SIN(RADIANS(J12))*10*BJ3 -> -10
I6: Las Logging Complete | J6: Yes | M6: Post "_C" Logging Exists | N6: No | AE6: G.L. | AF6: 1 | AG6: From Horizontal | AH6: Yes | AI6: Diamond | AK6: from checklite | AL6: GDA94 | AM6: 0001/11 | AN6: WATER | AO6: mm | AP6: 60s | AQ6: 10 | AR6: WESTERN AUSTRALIA | AS6: AAMC WONMUNNA | AT6: AAMC | AV6: AUSTRALIA | AX6: NO SURVEY - HOLE BLOCKED AT COLLAR | AY6: ACO | AZ6: ADAM CORRIE | BA6: From Horizontal | BD6: 5843S10361 | BE6: DGPS | BI6: =COS(RADIANS(J12))*5 -> 3.0628711e-16 | BJ6: =SIN(RADIANS(J12))*5*BJ3 -> -5
B7: Witness | AE7: D.F. | AF7: 2 | AH7: No | AI7: RC | AJ7: Dummy | AK7: =IF(ISNUMBER(VLOOKUP("DUMMY",'Cover Sheet'!$B$34:$AA$44,13,0)),(VLOOKUP("DUMMY",'Cover Sheet'!$B$34:$AA$44,24,0)),"") -> 0 | AL7: WGS84 | AM7: 0002/11 | AN7: KCL | AO7: in | AP7: 59s | AQ7: 20 | AR7: QUEENSLAND | AS7: ACCENT | AT7: ACCENT | AV7: CANADA | AX7: NO SURVEY - HOLE BLOCKED AT SURFACE | AY7: AGA | AZ7: ALFONSO GARCIA | BA7: From Horizontal | BD7: 5843S10461 | BE7: DGPS | BI7: =COS(RADIANS(J12/1.333))*5 -> 1.9120562 | BJ7: =SIN(RADIANS(J12/1.333))*5*BJ3 -> -4.6199612
B8: Client Signature | I8: Pad condition on leaving | J8: Good - clean stable surface | AE8: K.B. | AF8: 3 | AH8: NS | AI8: Chip | AJ8: 9012InRod | AK8: ='All Details'!HM2 -> 0 | AL8: NAD83 | AM8: 0013/10 | AN8: POLYMER | AP8: 58s | AQ8: 25 | AR8: NEW SOUTH WALES | AS8: AGNICO EAGLE | AT8: AGNICO EAGLE | AV8: USA | AX8: NO SURVEY - COLLAR DESTROYED | AY8: AL | AZ8: ALVARO GAYO | BA8: From Horizontal | BD8: 5843S10511 | BE8: DGPS | BI8: =COS(RADIANS(J12/2))*5 -> 3.5355339 | BJ8: =SIN(RADIANS(J12/2))*5*BJ3 -> -3.5355339
W9: QC Score | Y9: 1 | AF9: 4 | AI9: Mud Rotary | AJ9: 9238 | AK9: ='All Details'!IM2 -> 0 | AL9: NAD27 | AM9: 0015/10 | AN9: AIR | AP9: 57s | AQ9: 50 | AR9: NORTHERN TERRITORY | AS9: AIM MINING CORPORATION | AT9: AIM MINING CORPORATION | AV9: PHILIPPINES | AX9: NO SURVEY - COLLAR DAMAGED | AY9: ALG | AZ9: ANTHONY WILLIAMS | BA9: From Horizontal | BD9: 5843S10519 | BE9: DGPS | BI9: =COS(RADIANS(J12/4))*5 -> 4.6193977 | BJ9: =SIN(RADIANS(J12/4))*5*BJ3 -> -1.9134172
D10: *Only use "_ReEntry" if you have previously submited the completed hole. Don't use "_ReEntry" in the Trimble DGPS PtID. | X10: \ (•◡•) / 100% | AF10: 5 | AH10: Survey type | AI10: Air Core | AJ10: 9239 | AK10: ='All Details'!IZ2 -> 0 | AL10: UTM | AM10: 0016/10 | AN10: FOAM | AO10: kg/m | AP10: 56s | AQ10: 100 | AR10: SOUTH AUSTRALIA | AS10: API MANAGEMENT WEST PILBARA | AT10: API MANAGEMENT | AV10: LAOS | AX10: NO SURVEY - ACCESS DESTROYED | AY10: AMC | AZ10: MARK CHERRY | BA10: From Horizontal | BD10: 5843S10529 | BE10: DGPS | BI10: 5 | BJ10: 0
B11: Hole Name | D11: RC26VIV0007 | I11: Mag Declination | J11: 0.82 | R11: Mud Type | Y11: Detail Zones | AF11: 6 | AI11: PDC | AJ11: 9622 | AK11: ='All Details'!KZ2 -> 0 | AL11: LOCAL GRID | AM11: 0017/10 | AN11: OBM | AO11: lb/ft | AP11: 55s | AQ11: 200 | AR11: TASMANIA | AS11: AQUIFER RESOURCES | AT11: AQUIFER RESOURCES | AV11: MOZAMBIQUE | AX11: NO SURVEY - FIBROUS HOLE | AY11: AP | AZ11: ANTONIA PLANKENSTEINER | BA11: From Horizontal | BD11: 5843S10542 | BE11: DGPS | BI11: Azi Graph | BJ11: ="Azimuth = " & J13 -> Azimuth = 0
B12: Peg Number | D12: 12946 | I12: Planned Dip | J12: -90 | K12: From Horizontal | R12: Mud Weight | Y12: Top | AA12: Bottom | AF12: 7 | AH12: InRod/Rig | AI12: CASING TYPE | AJ12: 9057 | AK12: ='All Details'!HZ2 -> 0 | AL12: AGD84 | AM12: 002/10 | AN12: BARITE | AP12: 54s | AQ12: 500 | AR12: VICTORIA | AS12: AZURE MINERALS - ANDOVER | AT12: AZURE MINERALS | AV12: SOUTH AFRICA | AX12: NO SURVEY - POOR PAD CONDITIONS | AY12: BAEB | AZ12: BEN BAKER | BA12: From Horizontal | BD12: 5916S11991 | BE12: DGPS | BI12: 0 | BJ12: 0
B13: Deposit Code (Field) | D13: VIV | I13: Planned Azimuth | J13: 0 | R13: Salinity | T13: ppm | X13: 1 | AF13: 8 | AH13: Open Hole | AJ13: 9098-Gyro | AK13: ='All Details'!MM2 -> 0 | AM13: 003/10 | AO13: g/cc | AP13: 53s | AQ13: 1000 | AR13: ALBERTA | AS13: BELLEVUE GOLD | AT13: BELLEVUE GOLD | AV13: BOTSWANA | AX13: NO SURVEY - HOLE ABANDONED | AY13: BJD | AZ13: BENJAMIN CONNOR | BA13: From Horizontal | BI13: =SIN(RADIANS( J13))*9 -> 0 | BJ13: =COS(RADIANS( J13))*9 -> 9
B14: Tenement (Location) | D14: VIV | I14: Datum | J14: GDA94 | X14: 2 | AF14: 9 | AH14: Cased Hole | AI14: PVC | AJ14: 9321 | AK14: ='All Details'!JM2 -> 0 | AM14: 0909/12 | AO14: lbs/gal | AP14: 52s | AR14: BRITISH COLUMBIA | AS14: BELLS CORNER | AT14: BELLS CORNER | AY14: BSY | AZ14: BRENNAN YARDLEY | BA14: From Horizontal | BI14: Azi Graph - arrow part 1
B15: State / Prov | D15: WESTERN AUSTRALIA | I15: Grid Zone | J15: 50s | L15: Measured | N15: Difference | R15: Rm | X15: 3 | AF15: 10 | AH15: Thru Bit | AI15: STEEL | AJ15: 9510 | AK15: ='All Details'!KM2 -> 0 | AM15: 192 | AP15: 51s | AR15: LABRADOR | AS15: BHP NICKEL WEST | AT15: BHP NICKEL WEST | AX15: DGPS NOT COLLECTED - WATER BORE | AY15: CHE | AZ15: CHRIS HEAD | BA15: From Horizontal | BI15: =BI13 -> 0 | BJ15: =BJ13 -> 9
B16: Country | D16: AUSTRALIA | I16: Planned Easting | K16: E | N16: =IF(OR(L16="",J16=""),"",J16-L16) | O16: m | R16: Rmf | X16: 4 | AH16: InPVC | AI16: SLOTTED | AJ16: 9512 | AK16: ='All Details'!MZ2 -> 0 | AM16: 193 | AP16: 50s | AR16: MANITOBA | AS16: BIG BELL 2 | AT16: MINEGEOTECH | AX16: DGPS NOT COLLECTED - CHECK SHOT OUTSIDE OF TOLERANCE | AY16: CHG | AZ16: CHARLES GARDINER | BA16: From Horizontal | BI16: =BI15-COS(RADIANS(90-30- J13))*2 -> -1 | BJ16: =BJ15-SIN(RADIANS(90-30- J13))*2 -> 7.2679492
B17: Rig Number | I17: Planned Northing | K17: N | N17: =IF(OR(L17="",J17=""),"",J17-L17) | O17: m | R17: Rmc | X17: 5 | AH17: DGPS | AI17: NONE | AJ17: 3CAL | AK17: ='All Details'!NM2 -> 0 | AM17: 194 | AP17: 49s | AR17: NEW BRUNSWICK | AS17: BOSS RESOURCES | AT17: BOSS RESOURCES | AX17: DGPS NOT COLLECTED - NO SATELLITES RTX | AY17: CLH | AZ17: CAMERON HEATH | BA17: From Horizontal | BI17: Azi Graph - arrow part 2
I18: Elevation GL | K18: m | L18: Total Diff | N18: =IF(N17="","",SQRT(N16^2+N17^2)) | O18: m | X18: 6 | AI18: OTHER | AJ18: NorthGyro | AK18: ='All Details'!PM2 -> 0 | AM18: 195 | AP18: 48s | AR18: NEWFOUNDLAND | AS18: BREAKER RESOURCES | AT18: BREAKER RESOURCES | AX18: DGPS NOT COLLECTED - LIMITED SATELLITES RTX | AY18: CNC | AZ18: CHRISTOPHER CALLISON | BA18: From Horizontal | BI18: =BI15 -> 0 | BJ18: =BJ15 -> 9
B19: Drill Type | D19: RC | I19: Elevation DF | K19: m | R19: Circ Stopped | X19: 7 | AE19: Division | AG19: LoggingUnit | AJ19: GVGamma | AK19: ='All Details'!LM2 -> 0 | AM19: 196 | AP19: 47s | AR19: NW TERRITORIES | AS19: BUXTON RESOURCES | AT19: BUXTON RESOURCES | AX19: DGPS NOT COLLECTED - NO RADIO SIGNAL RTK | AY19: CPJ | AZ19: CALLUM JOSEY | BA19: From Horizontal | BI19: =BI18+SIN(RADIANS(30- J13))*2 -> 1 | BJ19: =BJ18-COS(RADIANS(30- J13))*2 -> 7.2679492
B20: Bit Size | D20: 14 | E20: cm | I20: Elevation KB | K20: m | R20: BH Temp | T20: Deg C | X20: 8 | AE20: PWS | AG20: 0705 | AJ20: ABI | AK20: ='All Details'!LZ2 -> 0 | AM20: 197 | AP20: 46s | AR20: NOVA SCOTIA | AS20: CARAVEL LTD - GILLINGARRA WATER BORES | AT20: CARAVEL MINERALS LIMITED | AX20: DGPS NOT COLLECTED - WOULD NOT CONVERGE RTX | AY20: CWR | AZ20: CHRIS REDMAN | BA20: From Horizontal
B21: Drillers TD (DTD) | D21: 36 | E21: m | I21: Drill Depth From | J21: G.L. | R21: Time Since Circ | T21: Hrs | X21: 9 | AE21: CWS | AG21: 0803 | AJ21: OBI | AK21: ='All Details'!JZ2 -> 0 | AM21: 1873CZ | AP21: 45s | AR21: NUNAVUT | AS21: CHALICE GOLD | AT21: CHALICE GOLD | AX21: DGPS NOT COLLECTED - XXXWHY?XXX | AY21: CX | AZ21: CONG XIAO | BA21: From Horizontal
B22: Loggers TD (LTD) | D22: 35.4 | E22: m | F22: =IF(D21<(D22+3),"","LTD >3m DTD Warning") | I22: Log Depth From | J22: G.L. | K22: m | R22: Fluid Level | S22: DRY | T22: m | X22: 10 | AE22: PPW | AG22: 0805 | AJ22: MCST | AK22: ='All Details'!OZ2 -> 0 | AM22: 1874CZ | AP22: 44s | AR22: ONTARIO | AS22: CYPRIUM METALS | AT22: NIFTY COPPER MINE | AX22: IN ROD COLLECTED WITH 9139 | AY22: DAP | AZ22: DARRYL PAGE | BA22: From Horizontal
B23: Casing Shoe Driller | E23: m | X23: 11 | AE23: WSG | AG23: 0806 | AJ23: DGPS | AK23: ='All Details'!PZ2 -> 0 | AM23: 2281CN | AP23: 43s | AR23: PRINCE EDWARD ISLAND | AS23: DE GREY MINING | AT23: DE GREY MINING | AX23: DENSITY TOOL HUNG AT XX.Xm – DENSITY SURVEY TO XXm | AY23: DJM | AZ23: DAVID METCALFE | BA23: From Horizontal
B24: Casing Shoe Logger | E24: m | I24: Rig Stickup for Header | K24: m | X24: 12 | AG24: 1003 | AJ24: SpectralGamma | AK24: ='All Details'!QM2 -> 0 | AM24: 2282CN | AP24: 42s | AR24: QUEBEC | AS24: ELEVATE URANIUM LIMITED | AT24: ELEVATE URANIUM LIMITED | AX24: NO DENSITY SURVEY – OPEN HOLE BLOCKED AT XXm | AY24: DQU | AZ24: DOM QUINLIVAN | BA24: From Horizontal
B25: Casing OD | I25: Cas Stickup for Header | K25: m | R25: Repeat Section | X25: 13 | AG25: 1005 | AJ25: IRD | AK25: ='All Details'!QZ2 -> 0 | AM25: 2325 | AP25: 41s | AR25: SASKATCHEWAN | AS25: FMGL CHRISTMAS CREEK | AT25: FMGL MINES | AX25: NO DENSITY SURVEY ABOVE XXm – TOOL STUCK ON UPRUN | AY25: DRM | AZ25: DONALD MBANGANI | BA25: From Horizontal
B26: Casing ID | X26: 14 | AG26: 1201 | AJ26: BMR | AK26: ='All Details'!RM2 -> 0 | AM26: 4507NE | AP26: 40s | AR26: YUKON | AS26: FMGL CLOUDBREAK | AT26: FMGL MINES | AY26: DRU | AZ26: DENNIS RUTTEN | BA26: From Horizontal
B27: Casing Weight | I27: Neutron source used | J27: No | X27: 15 | AE27: Acquisition Interval (cm) | AG27: 1206 | AJ27: IND | AK27: ='All Details'!NZ2 -> 0 | AM27: 8715CN/RN940 | AP27: 39s | AS27: FMGL ELIWANA | AT27: FMGL MINES | AX27: NO OPEN HOLE SURVEY - OPEN HOLE BLOCKED AT XXm | AY27: DRZ | AZ27: DANIEL ZAMARCA | BA27: From Horizontal
B28: Casing Type | D28: PVC | I28: Density source used | J28: Yes | R28: SP Scale | AE28: 1 | AG28: 1208 | AJ28: EM51 | AK28: ='All Details'!OM2 -> 0 | AM28: CZ1872 | AP28: 38s | AS28: FMGL SOLOMON | AT28: FMGL MINES | AX28: NO OPEN HOLE SURVEY - OPEN HOLE BLOCKED AT COLLAR | AY28: DVH | AZ28: DEAN VAN HEEZIK | BA28: From Horizontal
B29: Prod. casing OD | E29: mm | AE29: 10 | AG29: 1301 | AJ29: FLOW | AK29: ='All Details'!RZ2 -> 0 | AM29: L516 | AP29: 37s | AS29: FMGX EXPLORATION | AT29: FMGL EXPLORATION | AX29: NO OPEN HOLE SURVEY - OPEN HOLE BLOCKED AT SURFACE | AY29: ERC | AZ29: EDER RODRIGUES COSTA | BA29: From Horizontal
F30: Enter N or | U30: DEPTH CONTROL | AE30: 50 | AG30: 1401 | AJ30: DHEM | AK30: ='All Details'!SM2 -> 0 | AM30: L579 | AP30: 36s | AS30: FQM RAVENSTHORPE | AT30: FIRST QUANTUM MINERALS | AX30: NO OPEN HOLE SURVEY - COLLAR DESTROYED | AY30: FN | AZ30: FADLI NEWELL | BA30: From Horizontal
F31: Hangup Depth | Q31: Start | U31: End | Y31: Suggested | AA31: Correction | AE31: 100 | AG31: 1501 | AJ31: DGPS | AK31: 0 | AM31: L670 | AP31: 35s | AS31: GHD GEOTECH FORRESTFIELD | AT31: GHD | AX31: NO OPEN HOLE SURVEY - COLLAR DAMAGED | AY31: GJL | AZ31: GREGORY LICATA | BA31: From Horizontal
B32: Tool | F32: Tool | H32: Lead | I32: Logging | L32: Depth | N32: Depth | Q32: Shoulder | S32: Encoder | U32: Shoulder | W32: Encoder | Y32: depth | AA32: Applied | AG32: 1502 | AM32: PE551 | AP32: 34s | AS32: GOLDEN GROVE | AT32: MINEGEOTECH | AX32: NO OPEN HOLE SURVEY - ACCESS DESTROYED | AY32: GMF | AZ32: GLEN FOX | BA32: From Horizontal
B33: Type | C33: Serial# | D33: Source | E33: Survey Type | F33: Hang Up | G33: Date | H33: Operator | I33: Unit | J33: Start Time | K33: Finish Time | L33: Top | N33: Bottom | P33: Stickup | Q33: Offset | S33: Depth | U33: Offset | W33: Depth | Y33: correction | AA33: by checklite | AG33: 1701 | AM33: PE555 | AP33: 33s | AS33: GWR HATCHES CREEK | AT33: GWR | AX33: NO OPEN HOLE SURVEY - FIBROUS HOLE | AY33: HKA | AZ33: GUILLAUME DELORME | BA33: From Horizontal
B34: Dummy | C34: =IF(ISNA(VLOOKUP(B34,$S$59:$AB$70,3,0)),"",(VLOOKUP(B34,$S$59:$AB$70,3,0))) -> 0 | D34: =IF(B34="","",IF(ISBLANK(VLOOKUP(B34,$S$59:$AB$70,5,0)),"",(VLOOKUP(B34,$S$59:$AB$70,5,0)))) -> - | E34: Open Hole | F34: N | G34: 46102 | H34: TJJ | I34: =IF(ISNA(VLOOKUP(B34,$S$59:$AB$70,7,0)),"",(VLOOKUP(B34,$S$59:$AB$70,7,0))) -> 2107 | J34: 0.4375 | K34: 0.45833333 | L34: 0 | N34: 35.4 | P34: 0 | Q34: 0 | R34: m | S34: =IF(B34="-","",-Q34-P34) -> 0 | T34: m | U34: 0 | W34: 0 | X34: m | Y34: =IF($S$4=1,IF(B34="-",0,TRUNC(-(W34+U34+P34),2)),IF(B34="-",0,ROUND(-(W34+U34+P34),1))) -> 0 | Z34: m | AA34: =IF(B34="","",VLOOKUP(B34,$AJ$7:$AK$31,2,FALSE)) -> 0 | AB34: m | AG34: 1702 | AM34: PE574 | AP34: 32s | AS34: HANCOCK PROSPECTING | AT34: HANCOCK PROSPECTING | AX34: NO OPEN HOLE SURVEY - POOR PAD CONDITIONS | AY34: JAM | AZ34: JASON MATHER | BA34: From Horizontal
B35: 9622 | C35: =IF(ISNA(VLOOKUP(B35,$S$59:$AB$70,3,0)),"",(VLOOKUP(B35,$S$59:$AB$70,3,0))) -> 4364 | D35: =IF(B35="","",IF(ISBLANK(VLOOKUP(B35,$S$59:$AB$70,5,0)),"",(VLOOKUP(B35,$S$59:$AB$70,5,0)))) -> - | E35: Open Hole | F35: N | G35: 46102 | H35: TJJ | I35: =IF(ISNA(VLOOKUP(B35,$S$59:$AB$70,7,0)),"",(VLOOKUP(B35,$S$59:$AB$70,7,0))) -> 2107 | J35: 0.45833333 | K35: 0.47916667 | L35: 0 | N35: 35.4 | P35: 0 | Q35: 0 | R35: m | S35: =IF(B35="-","",-Q35-P35) -> 0 | T35: m | U35: 0 | W35: 0 | X35: m | Y35: =IF($S$4=1,IF(B35="-",0,TRUNC(-(W35+U35+P35),2)),IF(B35="-",0,ROUND(-(W35+U35+P35),1))) -> 0 | Z35: m | AA35: =IF(B35="","",VLOOKUP(B35,$AJ$7:$AK$31,2,FALSE)) -> 0 | AB35: m | AG35: 1703 | AM35: PE597 | AP35: 31s | AS35: IGO | AT35: IGO DHEM | AY35: JCD | AZ35: JAYDEN DANIELS | BA35: From Horizontal
B36: 9239 | C36: =IF(ISNA(VLOOKUP(B36,$S$59:$AB$70,3,0)),"",(VLOOKUP(B36,$S$59:$AB$70,3,0))) -> 2766 | D36: =IF(B36="","",IF(ISBLANK(VLOOKUP(B36,$S$59:$AB$70,5,0)),"",(VLOOKUP(B36,$S$59:$AB$70,5,0)))) -> H003/21 | E36: Open Hole | F36: N | G36: 46102 | H36: TJJ | I36: =IF(ISNA(VLOOKUP(B36,$S$59:$AB$70,7,0)),"",(VLOOKUP(B36,$S$59:$AB$70,7,0))) -> 2107 | J36: 0.47916667 | K36: 0.5 | L36: 0 | N36: 34.4 | P36: 0 | Q36: 0 | R36: m | S36: =IF(B36="-","",-Q36-P36) -> 0 | T36: m | U36: 0 | W36: 0 | X36: m | Y36: =IF($S$4=1,IF(B36="-",0,TRUNC(-(W36+U36+P36),2)),IF(B36="-",0,ROUND(-(W36+U36+P36),1))) -> 0 | Z36: m | AA36: =IF(B36="","",VLOOKUP(B36,$AJ$7:$AK$31,2,FALSE)) -> 0 | AB36: m | AG36: 1801 | AM36: PE606 | AP36: 30s | AS36: IOC | AT36: IOC | AX36: OPEN HOLE BLOCKED AT XXm | AY36: JCL | AZ36: JEFF LOHREY | BA36: From Horizontal
B37: OBI | C37: =IF(ISNA(VLOOKUP(B37,$S$59:$AB$70,3,0)),"",(VLOOKUP(B37,$S$59:$AB$70,3,0))) -> 1118 | D37: =IF(B37="","",IF(ISBLANK(VLOOKUP(B37,$S$59:$AB$70,5,0)),"",(VLOOKUP(B37,$S$59:$AB$70,5,0)))) -> - | E37: Open Hole | F37: N | G37: 46102 | H37: TJJ | I37: =IF(ISNA(VLOOKUP(B37,$S$59:$AB$70,7,0)),"",(VLOOKUP(B37,$S$59:$AB$70,7,0))) -> 2107 | J37: 0.5 | K37: 0.52083333 | L37: 0 | N37: 34.4 | P37: 0 | Q37: 0 | R37: m | S37: =IF(B37="-","",-Q37-P37) -> 0 | T37: m | U37: 0 | W37: 0 | X37: m | Y37: =IF($S$4=1,IF(B37="-",0,TRUNC(-(W37+U37+P37),2)),IF(B37="-",0,ROUND(-(W37+U37+P37),1))) -> 0 | Z37: m | AA37: =IF(B37="","",VLOOKUP(B37,$AJ$7:$AK$31,2,FALSE)) -> 0 | AB37: m | AG37: 1802 | AM37: PE619 | AP37: 29s | AS37: IRONBRIDGE | AT37: IRONBRIDGE | AX37: HOLE BLOCKED AT SURFACE | AY37: JDT | AZ37: JON TEMBY | BA37: From Horizontal
B38: DGPS | C38: =IF(ISNA(VLOOKUP(B38,$S$59:$AB$70,3,0)),"",(VLOOKUP(B38,$S$59:$AB$70,3,0))) -> 5843S10542 | D38: =IF(B38="","",IF(ISBLANK(VLOOKUP(B38,$S$59:$AB$70,5,0)),"",(VLOOKUP(B38,$S$59:$AB$70,5,0)))) -> - | E38: Open Hole | F38: N | G38: 46102 | H38: TJJ | I38: =IF(ISNA(VLOOKUP(B38,$S$59:$AB$70,7,0)),"",(VLOOKUP(B38,$S$59:$AB$70,7,0))) -> 2107 | J38: 0.52083333 | K38: 0.54166667 | L38: 0 | N38: 0 | P38: 0 | Q38: 0 | R38: m | S38: =IF(B38="-","",-Q38-P38) -> 0 | T38: m | U38: 0 | W38: 0 | X38: m | Y38: =IF($S$4=1,IF(B38="-",0,TRUNC(-(W38+U38+P38),2)),IF(B38="-",0,ROUND(-(W38+U38+P38),1))) -> 0 | Z38: m | AA38: =IF(B38="","",VLOOKUP(B38,$AJ$7:$AK$31,2,FALSE)) -> 0 | AB38: m | AE38: Fluid Level | AG38: 1803 | AM38: R037 | AP38: 28s | AS38: JAGUAR | AT38: ROUND OAK MINERALS | AX38: HOLE BLOCKED AT XXm | AY38: JJD | AZ38: JAMES DANIEL | BA38: From Horizontal
C39: =IF(ISNA(VLOOKUP(B39,$S$59:$AB$70,3,0)),"",(VLOOKUP(B39,$S$59:$AB$70,3,0))) | D39: =IF(B39="","",IF(ISBLANK(VLOOKUP(B39,$S$59:$AB$70,5,0)),"",(VLOOKUP(B39,$S$59:$AB$70,5,0)))) | I39: =IF(ISNA(VLOOKUP(B39,$S$59:$AB$70,7,0)),"",(VLOOKUP(B39,$S$59:$AB$70,7,0))) | R39: m | S39: =IF(B39="-","",-Q39-P39) -> 0 | T39: m | X39: m | Y39: =IF($S$4=1,IF(B39="-",0,TRUNC(-(W39+U39+P39),2)),IF(B39="-",0,ROUND(-(W39+U39+P39),1))) -> 0 | Z39: m | AA39: =IF(B39="","",VLOOKUP(B39,$AJ$7:$AK$31,2,FALSE)) | AB39: m | AG39: 1804 | AM39: R038 | AP39: 27s | AS39: KARARA MINING LIMITED | AT39: KARARA MINING LIMITED | AX39: NO INROD SURVEY | AY39: JKK | AZ39: JIM KADURU | BA39: From Horizontal
C40: =IF(ISNA(VLOOKUP(B40,$S$59:$AB$70,3,0)),"",(VLOOKUP(B40,$S$59:$AB$70,3,0))) | D40: =IF(B40="","",IF(ISBLANK(VLOOKUP(B40,$S$59:$AB$70,5,0)),"",(VLOOKUP(B40,$S$59:$AB$70,5,0)))) | I40: =IF(ISNA(VLOOKUP(B40,$S$59:$AB$70,7,0)),"",(VLOOKUP(B40,$S$59:$AB$70,7,0))) | R40: m | S40: =IF(B40="-","",-Q40-P40) -> 0 | T40: m | X40: m | Y40: =IF($S$4=1,IF(B40="-",0,TRUNC(-(W40+U40+P40),2)),IF(B40="-",0,ROUND(-(W40+U40+P40),1))) -> 0 | Z40: m | AA40: =IF(B40="","",VLOOKUP(B40,$AJ$7:$AK$31,2,FALSE)) | AB40: m | AE40: DRY | AG40: 1901 | AM40: R039 | AP40: 26s | AS40: LYNAS RARE EARTHS | AT40: LYNAS RARE EARTHS | AX40: INROD NOT COLLECTED BY WSG | AY40: JLA | AZ40: JORDAN ALWEYN | BA40: From Horizontal
...

Sheet Data for Monthly Spreadsheet
A1: PWS
A3: Hole Name | B3: Tenement ID | C3: Easting | D3: Northing | E3: Planned Dip | F3: Planned Azimuth | G3: PEG No. | H3: Drilled Depth | I3: Inrod Date | J3: InRod Operator | K3: InRods Truck Number | L3: Magnetic Susceptibility Date | M3: Density Date | N3: Open Hole Operator | O3: Open Hole Truck Number | P3: OTV Date | Q3: ATV Date | R3: Image Operator | S3: Image Truck Number | T3: Completed Hole? | U3: Comments Line 1 | V3: Comments Line 2 | W3: Comments Line 3 | X3: Comments Line 4
A4: ='All Details'!A2 -> RC26VIV0007 | B4: ='All Details'!E2 -> VIV | C4: ='All Details'!U2 | D4: ='All Details'!T2 | E4: ='All Details'!AB2 -> -90 | F4: ='All Details'!AC2 -> 0 | G4: ='All Details'!B2 -> 12946 | H4: ='All Details'!O2 -> 36 | I4: ='All Details'!DZ2 | J4: ='All Details'!DR2 | L4: ='All Details'!KR2 -> 46102 | M4: ='All Details'!IE2 | N4: ='All Details'!DS2 -> TJJ | O4: ='All Details'!DV2 -> 2107 | P4: ='All Details'!LR2 -> 46102 | Q4: ='All Details'!LE2 | R4: ='All Details'!FJ2 -> TJJ | S4: ='All Details'!FI2 | T4: ='All Details'!L2 -> Yes | U4: ='All Details'!AN2 | V4: ='All Details'!AO2 | W4: ='All Details'!AP2 | X4: ='All Details'!AQ2 | Y4: ='All Details'!AR2
A7: PPW
A9: Hole Name | B9: Tenement ID | C9: Easting | D9: Northing | E9: Planned Dip | F9: Planned Azimuth | G9: Drilled Depth | H9: TGT Depth | I9: TGT Date | J9: TGT Operator | K9: Service Co | L9: Truck Number | M9: GYRO Depth | N9: GYRO Date | O9: GYRO Operator | P9: Service Co | Q9: Truck Number | R9: Gyro hang up in rods | S9: Mag Susc Date | T9: Mag Susc Depth | U9: Density Date | V9: Density Depth | W9: Conductivity Date | X9: Conductivity Depth | Y9: Open Hole Operator | Z9: Service Company | AA9: Open Hole Truck Number | AB9: OTV date | AC9: OTV depth | AD9: OTV Op | AE9: ATV date | AF9: ATV Depth | AG9: ATV OP | AH9: Approx Water Table Depth | AI9: Steel Casing Depth | AJ9: Gyro? | AK9: Completed Hole? | AL9: Pad Condition WHEN LEFT | AM9: Logging Operator Comments | AN9: % hole open hole logged | AO9: Density Tool no | AP9: Density Source No | AQ9: Triple GAMMA Tool No | AR9: K_factor | BA9: TOP Depth | BB9: Bottom Depth (Open Hole) | BC9: Bottom Depth (All runs) | BD9: Last Log Date
A10: ='All Details'!A2 -> RC26VIV0007 | B10: ='All Details'!E2 -> VIV | C10: ='All Details'!U2 | D10: ='All Details'!T2 | E10: ='All Details'!AB2 -> -90 | F10: ='All Details'!AC2 -> 0 | G10: ='All Details'!O2 -> 36 | H10: ='All Details'!DW2 | I10: ='All Details'!DZ2 | J10: ='All Details'!DR2 | K10: PPW | L10: ='All Details'!DU2 | M10: ='All Details'!MX2 | N10: ='All Details'!MR2 | O10: ='All Details'!MS2 | P10: PPW | Q10: ='All Details'!MT2 | R10: ='All Details'!MQ2 | S10: ='All Details'!KR2 -> 46102 | T10: ='All Details'!KX2 -> 35.4 | U10: ='All Details'!IE2 | V10: ='All Details'!IK2 | W10: ='All Details'!KE2 | X10: ='All Details'!KK2 | Y10: ='All Details'!DS2 -> TJJ | Z10: PPW | AA10: ='All Details'!DV2 -> 2107 | AB10: ='All Details'!LR2 -> 46102 | AC10: ='All Details'!LX2 -> 34.4 | AD10: ='All Details'!LS2 -> TJJ | AE10: ='All Details'!LE2 | AF10: ='All Details'!LK2 | AG10: ='All Details'!LF2 | AH10: ='All Details'!AD2 -> DRY | AI10: ='All Details'!S2 -> 0 | AJ10: ='All Details'!DY2 | AK10: ='All Details'!L2 -> Yes | AL10: ='All Details'!DL2 -> Good - clean stable surface | AM10: ='All Details'!AN2 | AO10: ='All Details'!IA2 | AP10: ='All Details'!IB2 | AQ10: ='All Details'!NN2

Sheet All Details
A1: HoleName | B1: PEGNUMBER | C1: Client | D1: Field_ID | E1: Location | F1: State_Prov | G1: Country | H1: JobNo | I1: Date | J1: Unit | K1: Crew | L1: CompletedHole | M1: Witness | N1: BitSize | O1: DrillersTD | P1: LoggerTD | Q1: CasingOD | R1: DrillerCasing | S1: LoggerCasing | T1: Northing | U1: Easting | V1: ElevGL | W1: ElevDF | X1: ElevKB | Y1: DrillDepthfrom | Z1: LogDepthFrom | AA1: Stickup | AB1: PlannedDip | AC1: PlannedAzimuth | AD1: FluidLevel | AE1: MudRes | AF1: MudTemp | AG1: FluidType | AH1: RigNumber | AI1: MagDec | AJ1: SPLEFT | AK1: SPRIGHT | AL1: REPEATTOP | AM1: REPEATBOTTOM | AN1: REMARKS1 | AO1: REMARKS2 | AP1: REMARKS3 | AQ1: REMARKS4 | AR1: REMARKS5 | AS1: REMARKS6 | AT1: OpticalBoreholeVisibility | AU1: OpticalWaterClarity | AV1: FluidDENSITY | AW1: SALINITY | AX1: RMat25 | AY1: RMFat25 | AZ1: RMCat25 | BA1: TIMESINCECIRC | BB1: stopcirc | BC1: BHT | BD1: HEADERGL | BE1: HEADERDF | BF1: HEADERKB | BG1: Drillmeasuredfrom | BH1: Logmeasuredfrom | BI1: Inrod_Openhole_Cased_PVC | BJ1: TOPDepth | BK1: BottomDepth_OpenHole_ | BL1: BottomDepth_Allruns_ | BM1: LastLogDate | BN1: DetailTop1 | BO1: DetailBottom1 | BP1: DetailTop2 | BQ1: DetailBottom2 | BR1: DetailTop3 | BS1: DetailBottom3 | BT1: DetailTop4 | BU1: DetailBottom4 | BV1: DetailTop5 | BW1: DetailBottom5 | BX1: DetailTop6 | BY1: DetailBottom6 | BZ1: DetailTop7 | CA1: DetailBottom7 | CB1: DetailTop8 | CC1: DetailBottom8 | CD1: DetailTop9 | CE1: DetailBottom9 | CF1: DetailTop10 | CG1: DetailBottom10 | CH1: DetailTop11 | CI1: DetailBottom11 | CJ1: DetailTop12 | CK1: DetailBottom12 | CL1: DetailTop13 | CM1: DetailBottom13 | CN1: DetailTop14 | CO1: DetailBottom14 | CP1: DetailTop15 | CQ1: DetailBottom15 | CR1: HeaderRigStickup | CS1: HeaderCasingStickup | CT1: LASRigStickup | CU1: LASCasingStickup | CV1: LASFluidDensity | CW1: DCTCALINFO | CX1: NDECALINFO | CY1: CASINGTYPE | CZ1: CASINGTHICKNESS | DA1: PRODCASINGOD | DB1: Datum | DC1: CompanyCode | DD1: OthercommentsLine1 | DE1: OthercommentsLine2 | DF1: OthercommentsLine3 | DG1: RTIOHUB | DH1: RTXDATE | DI1: NeutronSourceUsed | DJ1: DensitySourceUsed | DK1: COMPANYDIVISION | DL1: PADCONDITION | DM1: FIELD | DN1: COMPANYDIVISIONa | DO1: COMPANYDIVISIONb | DP1: COMPANYDIVISIONC | DQ1: GyroOp | DR1: InrodOp | DS1: OpenOp | DT1: GyroUnit | DU1: InRodUnit | DV1: OpenUnit | DW1: InRod Gamma Depth | DX1: HDRFluidLevel | DY1: Gyrodate | DZ1: InRodDate | EA1: Gyrocommentline1 | EB1: Gyrocommentline2 | EC1: GyroAPSbearing | ED1: GyroAPSSignal | EE1: GyroCompassbearing | EF1: HandheldGPSGyroRef | EG1: HandheldGPSGyroEasting | EH1: HandheldGPSGyroNorthing | EI1: HandheldGPSSighterReference | EJ1: HandheldGPSSighterEasting | EK1: HandheldGPSSighterNorthing | EL1: HandheldGPSdE | EM1: HandheldGPSdN | EN1: HandheldGPSDistance | EO1: HandheldGPSBearing | EP1: FluidVIS | EQ1: RunID | ER1: DGPSGyroRef | ES1: DGPSGyroEasting | ET1: DGPSGyroNorthing | EU1: DGPSSighterReference | EV1: DGPSSighterEasting | EW1: DGPSSighterNorthing | EX1: DGPSdE | EY1: DGPSdN | EZ1: DGPSDistance | FA1: DGPSBearing | FB1: HDRDrillmeasuredfrom | FC1: HDRLogmeasuredfrom | FD1: SPMGyroTotalDrift | FE1: SPMGyroSurveyTime | FF1: SPMGyroDriftMin | FG1: SPMGyroDriftHour | FH1: SPMGyroDriftBust | FI1: ImageUnit | FJ1: ImageOp | FK1: MEMSGyroInrunRotation | FL1: MEMSGyroOutrunRotation | FM1: MEMSGyroInrunStartAzi | FN1: MEMSGyroOutrunStartAzi | FO1: MEMSGyroInvsOut | FP1: Caldate1 | FQ1: CalType1 | FR1: CalSerial1 | FS1: CalSource1 | FT1: CalUnit1 | FU1: CalHoleNme1 | FV1: Caldate2 | FW1: CalType2 | FX1: CalSerial2 | FY1: CalSource2 | FZ1: CalUnit2 | GA1: CalHoleNme2 | GB1: Caldate3 | GC1: CalType3 | GD1: CalSerial3 | GE1: CalSource3 | GF1: CalUnit3 | GG1: CalHoleNme3 | GH1: Caldate4 | GI1: CalType4 | GJ1: CalSerial4 | GK1: CalSource4 | GL1: CalUnit4 | GM1: CalHoleNme4 | GN1: DPCcomments | GO1: DataProcessingComplete | GP1: GeophysicsUploaded | GQ1: GyroUploaded | GR1: BHTVUploaded | GS1: OPTVUploaded | GT1: MCSTUploaded | GU1: TGTUploaded | GV1: _9012InRodToolSerial | GW1: OBISerialNo | GX1: ABISerialNo | GY1: _9098SerialNo | GZ1: TGTSerialNo | HA1: _9012SerialNumber | HB1: _9012Sourcenumber | HC1: _9012SurveyType | HD1: _9012ToolHangup | HE1: _9012Date | HF1: _9012Operator | HG1: _9012LoggingUnit | HH1: _9012Starttime | HI1: _9012Finishtime | HJ1: _9012Depthtop | HK1: _9012DepthBottom | HL1: _9012DepthCorrectioncalculated | HM1: _9012DepthCorrectionApplied | HN1: _9057SerialNumber | HO1: _9057Sourcenumber | HP1: _9057SurveyType | HQ1: _9057ToolHangup | HR1: _9057Date | HS1: _9057Operator | HT1: _9057LoggingUnit | HU1: _9057Starttime | HV1: _9057Finishtime | HW1: _9057Depthtop | HX1: _9057DepthBottom | HY1: _9057DepthCorrectioncalculated | HZ1: _9057DepthCorrectionApplied | IA1: _9238SerialNumber | IB1: _9238Sourcenumber | IC1: _9238SurveyType | ID1: _9238ToolHangup | IE1: _9238Date | IF1: _9238Operator | IG1: _9238LoggingUnit | IH1: _9238Starttime | II1: _9238Finishtime | IJ1: _9238Depthtop | IK1: _9238DepthBottom | IL1: _9238DepthCorrectioncalculated | IM1: _9238DepthCorrectionApplied | IN1: _9239SerialNumber | IO1: _9239Sourcenumber | IP1: _9239SurveyType | IQ1: _9239ToolHangup | IR1: _9239Date | IS1: _9239Operator | IT1: _9239LoggingUnit | IU1: _9239Starttime | IV1: _9239Finishtime | IW1: _9239Depthtop | IX1: _9239DepthBottom | IY1: _9239DepthCorrectioncalculated | IZ1: _9239DepthCorrectionApplied | JA1: _9321SerialNumber | JB1: _9321Sourcenumber | JC1: _9321SurveyType | JD1: _9321ToolHangup | JE1: _9321Date | JF1: _9321Operator | JG1: _9321LoggingUnit | JH1: _9321Starttime | JI1: _9321Finishtime | JJ1: _9321Depthtop | JK1: _9321DepthBottom | JL1: _9321DepthCorrectioncalculated | JM1: _9321DepthCorrectionApplied | JN1: MCSTSerialNumber | JO1: MCSTSourcenumber | JP1: MCSTSurveyType | JQ1: MCSTToolHangup | JR1: MCSTDate | JS1: MCSTOperator | JT1: MCSTLoggingUnit | JU1: MCSTStarttime | JV1: MCSTFinishtime | JW1: MCSTDepthtop | JX1: MCSTDepthBottom | JY1: MCSTDepthCorrectioncalculated | JZ1: MCSTDepthCorrectionApplied | KA1: _9510SerialNumber | KB1: _9510Sourcenumber | KC1: _9510SurveyType | KD1: _9510ToolHangup | KE1: _9510Date | KF1: _9510Operator | KG1: _9510LoggingUnit | KH1: _9510Starttime | KI1: _9510Finishtime | KJ1: _9510Depthtop | KK1: _9510DepthBottom | KL1: _9510DepthCorrectioncalculated | KM1: _9510DepthCorrectionApplied | KN1: _9622SerialNumber | KO1: _9622Sourcenumber | KP1: _9622SurveyType | KQ1: _9622ToolHangup | KR1: _9622Date | KS1: _9622Operator | KT1: _9622LoggingUnit | KU1: _9622Starttime | KV1: _9622Finishtime | KW1: _9622Depthtop | KX1: _9622DepthBottom | KY1: _9622DepthCorrectioncalculated | KZ1: _9622DepthCorrectionApplied | LA1: ABISerialNumber | LB1: ABISourcenumber | LC1: ABISurveyType | LD1: ABIToolHangup | LE1: ABIDate | LF1: ABIOperator | LG1: ABILoggingUnit | LH1: ABIStarttime | LI1: ABIFinishtime | LJ1: ABIDepthtop | LK1: ABIDepthBottom | LL1: ABIDepthCorrectioncalculated | LM1: ABIDepthCorrectionApplied | LN1: OBISerialNumber | LO1: OBISourcenumber | LP1: OBISurveyType | LQ1: OBIToolHangup | LR1: OBIDate | LS1: OBIOperator | LT1: OBILoggingUnit | LU1: OBIStarttime | LV1: OBIFinishtime | LW1: OBIDepthtop | LX1: OBIDepthBottom | LY1: OBIDepthCorrectioncalculated | LZ1: OBIDepthCorrectionApplied | MA1: GYRO_9098SerialNumber | MB1: GYRO_9098Sourcenumber | MC1: GYRO_9098SurveyType | MD1: GYRO_9098ToolHangup | ME1: GYRO_9098Date | MF1: GYRO_9098Operator | MG1: GYRO_9098LoggingUnit | MH1: GYRO_9098Starttime | MI1: GYRO_9098Finishtime | MJ1: GYRO_9098Depthtop | MK1: GYRO_9098DepthBottom | ML1: GYRO_9098DepthCorrectioncalculated | MM1: GYRO_9098DepthCorrectionApplied | MN1: GYRO_MemsSerialNumber | MO1: GYRO_MemsSourcenumber | MP1: GYRO_MemsSurveyType | MQ1: GYRO_MemsToolHangup | MR1: GYRO_MemsDate | MS1: GYRO_MemsOperator | MT1: GYRO_MemsLoggingUnit | MU1: GYRO_MemsStarttime | MV1: GYRO_MemsFinishtime | MW1: GYRO_MemsDepthtop | MX1: GYRO_MemsDepthBottom | MY1: GYRO_MemsDepthCorrectioncalculated | MZ1: GYRO_MemsDepthCorrectionApplied | NA1: GYRO_NorthSerialNumber | NB1: GYRO_NorthSourcenumber | NC1: GYRO_NorthSurveyType | ND1: GYRO_NorthToolHangup | NE1: GYRO_NorthDate | NF1: GYRO_NorthOperator | NG1: GYRO_NorthLoggingUnit | NH1: GYRO_NorthStarttime | NI1: GYRO_NorthFinishtime | NJ1: GYRO_NorthDepthtop | NK1: GYRO_NorthDepthBottom | NL1: GYRO_NorthDepthCorrectioncalculated | NM1: GYRO_NorthDepthCorrectionApplied | NN1: TGTSerialNumber | NO1: TGTSourcenumber | NP1: TGTSurveyType | NQ1: TGTToolHangup | NR1: TGTDate | NS1: TGTOperator | NT1: TGTLoggingUnit | NU1: TGTStarttime | NV1: TGTFinishtime | NW1: TGTDepthtop | NX1: TGTDepthBottom | NY1: TGTDepthCorrectioncalculated | NZ1: TGTDepthCorrectionApplied | OA1: _3ACSerialNumber | OB1: _3ACSourcenumber | OC1: _3ACSurveyType | OD1: _3ACToolHangup | OE1: _3ACDate | OF1: _3ACOperator | OG1: _3ACLoggingUnit | OH1: _3ACStarttime | OI1: _3ACFinishtime | OJ1: _3ACDepthtop | OK1: _3ACDepthBottom | OL1: _3ACDepthCorrectioncalculated | OM1: _3ACDepthCorrectionApplied | ON1: XRFSerialNumber | OO1: XRFSourcenumber | OP1: XRFSurveyType | OQ1: XRFToolHangup | OR1: XRFDate | OS1: XRFOperator | OT1: XRFLoggingUnit | OU1: XRFStarttime | OV1: XRFFinishtime | OW1: XRFDepthtop | OX1: XRFDepthBottom | OY1: XRFDepthCorrectioncalculated | OZ1: XRFDepthCorrectionApplied | PA1: GVGammaSerialNumber | PB1: GVGammaSourcenumber | PC1: GVGammaSurveyType | PD1: GVGammaToolHangup | PE1: GVGammaDate | PF1: GVGammaOperator | PG1: GVGammaLoggingUnit | PH1: GVGammaStarttime | PI1: GVGammaFinishtime | PJ1: GVGammaDepthtop | PK1: GVGammaDepthBottom | PL1: GVGammaDepthCorrectioncalculated | PM1: GVGammaDepthCorrectionApplied | PN1: SpectralGammaSerialNumber | PO1: SpectralGammaSourcenumber | PP1: SpectralGammaSurveyType | PQ1: SpectralGammaToolHangup | PR1: SpectralGammaDate | PS1: SpectralGammaOperator | PT1: SpectralGammaLoggingUnit | PU1: SpectralGammaStarttime | PV1: SpectralGammaFinishtime | PW1: SpectralGammaDepthtop | PX1: SpectralGammaDepthBottom | PY1: SpectralGammaDepthCorrectioncalculated | PZ1: SpectralGammaDepthCorrectionApplied | QA1: IPSerialNumber | QB1: IPSourcenumber | QC1: IPSurveyType | QD1: IPToolHangup | QE1: IPDate | QF1: IPOperator | QG1: IPLoggingUnit | QH1: IPStarttime | QI1: IPFinishtime | QJ1: IPDepthtop | QK1: IPDepthBottom | QL1: IPDepthCorrectioncalculated | QM1: IPDepthCorrectionApplied | QN1: IRDSerialNumber | QO1: IRDSourcenumber | QP1: IRDSurveyType | QQ1: IRDToolHangup | QR1: IRDDate | QS1: IRDOperator | QT1: IRDLoggingUnit | QU1: IRDStarttime | QV1: IRDFinishtime | QW1: IRDDepthtop | QX1: IRDDepthBottom | QY1: IRDDepthCorrectioncalculated | QZ1: IRDDepthCorrectionApplied | RA1: NMRSerialNumber | RB1: NMRSourcenumber | RC1: NMRSurveyType | RD1: NMRToolHangup | RE1: NMRDate | RF1: NMROperator | RG1: NMRLoggingUnit | RH1: NMRStarttime | RI1: NMRFinishtime | RJ1: NMRDepthtop | RK1: NMRDepthBottom | RL1: NMRDepthCorrectioncalculated | RM1: NMRDepthCorrectionApplied | RN1: FLOWSerialNumber | RO1: FLOWSourcenumber | RP1: FLOWSurveyType | RQ1: FLOWToolHangup | RR1: FLOWDate | RS1: FLOWOperator | RT1: FLOWLoggingUnit | RU1: FLOWStarttime | RV1: FLOWFinishtime | RW1: FLOWDepthtop | RX1: FLOWDepthBottom | RY1: FLOWDepthCorrectioncalculated | RZ1: FLOWDepthCorrectionApplied | SA1: DHEMSerialNumber | SB1: DHEMSourcenumber | SC1: DHEMSurveyType | SD1: DHEMToolHangup | SE1: DHEMDate | SF1: DHEMOperator | SG1: DHEMLoggingUnit | SH1: DHEMStarttime | SI1: DHEMFinishtime | SJ1: DHEMDepthtop | SK1: DHEMDepthBottom | SL1: DHEMDepthCorrectioncalculated | SM1: DHEMDepthCorrectionApplied | SN1: TDEVSerialNumber | SO1: TDEVSourcenumber | SP1: TDEVSurveyType | SQ1: TDEVToolHangup | SR1: TDEVDate | SS1: TDEVOperator | ST1: TDEVLoggingUnit | SU1: TDEVStarttime | SV1: TDEVFinishtime | SW1: TDEVDepthtop | SX1: TDEVDepthBottom | SY1: TDEVDepthCorrectioncalculated | SZ1: TDEVDepthCorrectionApplied | TA1: DPC_Project | TB1: M_Easting | TC1: M_Northing | TD1: GridZone | TE1: DummySerialNumber | TF1: DummySurveyType | TG1: DummyToolHangup | TH1: DummyDate | TI1: DummyOperator | TJ1: DummyLoggingUnit | TK1: DummyStarttime | TL1: DummyFinishtime | TM1: DummyDepthtop | TN1: DummyDepthBottom | TO1: DGPSSerialNumber | TP1: DGPSSurveyType | TQ1: DGPSDate | TR1: DGPSOperator | TS1: DGPSLoggingUnit | TT1: DGPSStarttime | TU1: DGPSFinishtime | TV1: Cal1_CPS_lo | TW1: Cal1_CPS_hi | TX1: Cal2_CPS_lo | TY1: Cal2_CPS_hi | TZ1: Cal3_CPS_lo | UA1: Cal3_CPS_hi | UB1: Cal4_CPS_lo | UC1: Cal4_CPS_hi | UD1: Encoder
